Workbook

Sheet Cover
A1: VALUAI - VALUATION INPUT TEMPLATE
A3: IBBI Valuer Details
A4: Valuer Name | B4: Harshal Vibhakar Anjaria
A5: IBBI Registration No. | B5: IBBI/RV/03/2026/16120
A6: Asset Class | B6: Securities or Financial Assets
A7: Valuer Address | B7: A-23, Sharnam-9, Bh Satyam Status, Jodhpur Gam Road, Ramdevnagar, Ahmedabad- 380054
A9: Engagement Details
A10: Client Company Name
A11: Client CIN
A12: Client Registered Address
A13: Date of Appointment
A14: Valuation Date
A15: Date of Report
A16: Purpose of Valuation
A17: Statutory Reference
A19: Valuation Standards Applied
A20: Base of Value | B20: Fair Value
A21: Premise of Value | B21: Going Concern
A22: Valuation Standard Reference | B22: ICAI VS / IBBI VS / IVS 105
A24: Currency and Units
A25: Reporting Currency | B25: INR
A26: Units | B26: Millions
A28: Period Configuration
A29: Number of Historical Years (2 to 5) | B29: 3
A30: Number of Forecast Years (5 to 10) | B30: 5
A31: Stub Period Required? (Yes/No) | B31: No
A32: If Yes, Stub Period Months | B32: 0
A34: Methodology Toggles
A35: Discounting Convention | B35: Mid-Year
A36: WACC Input Mode | B36: CAPM Build-up
A37: Terminal Value Method | B37: Gordon Growth
A39: Valuation Use Case
A40: Use Case Type | B40: Standalone Valuation
A41: Investment Amount Being Raised (in template units)
A42: Pre-Investment Shares Outstanding (in millions)
A43: New Shares to be Issued (in millions)
A44: Post-Investment Shares Outstanding (in millions) | B44: =SUM(B42:B43) -> 0
A45: Discount Rate Method for DCF | B45: Run both with reconciliation
A46: Reconciliation Tolerance (%) | B46: 2
A48: LEGEND
...

Sheet Historical_PL
A1: HISTORICAL PROFIT & LOSS STATEMENT
A3: Particulars | B3: FY-4 | C3: FY-3 | D3: FY-2 | E3: FY-1 | F3: FY-0 (Latest)
A4: Year Ending Date
A6: REVENUE
A7: Revenue from Operations
A8: Other Income
A9: Total Revenue | B9: =SUM(B7:B8) -> 0 | C9: =SUM(C7:C8) -> 0 | D9: =SUM(D7:D8) -> 0 | E9: =SUM(E7:E8) -> 0 | F9: =SUM(F7:F8) -> 0
A11: COSTS AND EXPENSES
A12: Cost of Goods Sold / Variable Cost
A13: Employee Benefits Expense
A14: Other Operating Expenses
A15: Total Operating Costs | B15: =SUM(B12:B14) -> 0 | C15: =SUM(C12:C14) -> 0 | D15: =SUM(D12:D14) -> 0 | E15: =SUM(E12:E14) -> 0 | F15: =SUM(F12:F14) -> 0
A17: EBITDA | B17: =B9-B15 -> 0 | C17: =C9-C15 -> 0 | D17: =D9-D15 -> 0 | E17: =E9-E15 -> 0 | F17: =F9-F15 -> 0
A18: Depreciation and Amortisation
A19: EBIT | B19: =B17-B18 -> 0 | C19: =C17-C18 -> 0 | D19: =D17-D18 -> 0 | E19: =E17-E18 -> 0 | F19: =F17-F18 -> 0
A20: Finance Cost / Interest Expense
A21: Profit Before Tax (PBT) | B21: =B19-B20 -> 0 | C21: =C19-C20 -> 0 | D21: =D19-D20 -> 0 | E21: =E19-E20 -> 0 | F21: =F19-F20 -> 0
A22: Tax Expense
A23: Profit After Tax (PAT) | B23: =B21-B22 -> 0 | C23: =C21-C22 -> 0 | D23: =D21-D22 -> 0 | E23: =E21-E22 -> 0 | F23: =F21-F22 -> 0

Sheet Historical_BS
A1: HISTORICAL BALANCE SHEET
A3: Particulars | B3: FY-4 | C3: FY-3 | D3: FY-2 | E3: FY-1 | F3: FY-0 (Latest)
A4: As on Date
A6: EQUITY AND LIABILITIES
A7: Shareholders' Funds
A8: Equity Share Capital
A9: Reserves and Surplus
A10: Total Shareholders' Funds | B10: =SUM(B8:B9) -> 0 | C10: =SUM(C8:C9) -> 0 | D10: =SUM(D8:D9) -> 0 | E10: =SUM(E8:E9) -> 0 | F10: =SUM(F8:F9) -> 0
A11: Preference Share Capital (if any)
A13: Non-Current Liabilities
A14: Long-term Borrowings
A15: Deferred Tax Liabilities (Net)
A16: Other Non-Current Liabilities
A17: Total Non-Current Liabilities | B17: =SUM(B14:B16) -> 0 | C17: =SUM(C14:C16) -> 0 | D17: =SUM(D14:D16) -> 0 | E17: =SUM(E14:E16) -> 0 | F17: =SUM(F14:F16) -> 0
A19: Current Liabilities
A20: Short-term Borrowings
A21: Trade Payables
A22: Other Current Liabilities
A23: Short-term Provisions
A24: Total Current Liabilities | B24: =SUM(B20:B23) -> 0 | C24: =SUM(C20:C23) -> 0 | D24: =SUM(D20:D23) -> 0 | E24: =SUM(E20:E23) -> 0 | F24: =SUM(F20:F23) -> 0
A26: TOTAL EQUITY AND LIABILITIES | B26: =B24+B17+B10+B11 -> 0 | C26: =C24+C17+C10+C11 -> 0 | D26: =D24+D17+D10+D11 -> 0 | E26: =E24+E17+E10+E11 -> 0 | F26: =F24+F17+F10+F11 -> 0
A29: ASSETS
A30: Non-Current Assets
A31: Property, Plant and Equipment (Net)
A32: Capital Work-in-Progress
A33: Intangible Assets
A34: Long-term Loans and Advances
A35: Other Non-Current Assets
A36: Non-Current Investments
A37: Deferred Tax Assets (Net)
A38: Total Non-Current Assets | B38: =SUM(B31:B37) -> 0 | C38: =SUM(C31:C37) -> 0 | D38: =SUM(D31:D37) -> 0 | E38: =SUM(E31:E37) -> 0 | F38: =SUM(F31:F37) -> 0
A40: Current Assets
A41: Current Investments
A42: Inventories
A43: Trade Receivables
A44: Cash and Cash Equivalents
A45: Bank Balances (other than Cash & Equiv.)
A46: Short-term Loans and Advances
A47: Other Current Assets
A48: Total Current Assets | B48: =SUM(B41:B47) -> 0 | C48: =SUM(C41:C47) -> 0 | D48: =SUM(D41:D47) -> 0 | E48: =SUM(E41:E47) -> 0 | F48: =SUM(F41:F47) -> 0
...

Sheet Projections
A1: FORECAST FINANCIALS (PROJECTIONS)
A3: Particulars | B3: Stub | C3: FY+1 | D3: FY+2 | E3: FY+3 | F3: FY+4 | G3: FY+5 | H3: FY+6 | I3: FY+7 | J3: FY+8 | K3: FY+9 | L3: FY+10
A4: Year Ending Date
A6: 1. PROFIT & LOSS FORECAST
A7: Revenue from Operations
A8: Other Income
A9: Total Revenue | B9: =SUM(B7:B8) -> 0 | C9: =SUM(C7:C8) -> 0 | D9: =SUM(D7:D8) -> 0 | E9: =SUM(E7:E8) -> 0 | F9: =SUM(F7:F8) -> 0 | G9: =SUM(G7:G8) -> 0 | H9: =SUM(H7:H8) -> 0 | I9: =SUM(I7:I8) -> 0 | ... L9: =SUM(L7:L8) -> 0
A11: Cost of Goods Sold / Variable Cost
A12: Employee Benefits Expense
A13: Other Operating Expenses
A14: Total Operating Costs | B14: =SUM(B11:B13) -> 0 | C14: =SUM(C11:C13) -> 0 | D14: =SUM(D11:D13) -> 0 | E14: =SUM(E11:E13) -> 0 | F14: =SUM(F11:F13) -> 0 | G14: =SUM(G11:G13) -> 0 | H14: =SUM(H11:H13) -> 0 | I14: =SUM(I11:I13) -> 0 | ... L14: =SUM(L11:L13) -> 0
A16: EBITDA | B16: =B9-B14 -> 0 | C16: =C9-C14 -> 0 | D16: =D9-D14 -> 0 | E16: =E9-E14 -> 0 | F16: =F9-F14 -> 0 | G16: =G9-G14 -> 0 | H16: =H9-H14 -> 0 | I16: =I9-I14 -> 0 | ... L16: =L9-L14 -> 0
A17: Depreciation and Amortisation
A18: EBIT | B18: =B16-B17 -> 0 | C18: =C16-C17 -> 0 | D18: =D16-D17 -> 0 | E18: =E16-E17 -> 0 | F18: =F16-F17 -> 0 | G18: =G16-G17 -> 0 | H18: =H16-H17 -> 0 | I18: =I16-I17 -> 0 | ... L18: =L16-L17 -> 0
A20: 2. TAX COMPUTATION
A21: Effective Tax Rate (%) | B21: 0.25168 | C21: 0.25168 | D21: 0.25168 | E21: 0.25168 | F21: 0.25168 | G21: 0.25168 | H21: 0.25168 | I21: 0.25168 | J21: 0.25168 | K21: 0.25168 | L21: 0.25168
A22: Tax on EBIT | B22: =B18*B21 -> 0 | C22: =C18*C21 -> 0 | D22: =D18*D21 -> 0 | E22: =E18*E21 -> 0 | F22: =F18*F21 -> 0 | G22: =G18*G21 -> 0 | H22: =H18*H21 -> 0 | I22: =I18*I21 -> 0 | ... L22: =L18*L21 -> 0
A23: NOPAT (EBIT × (1 - Tax)) | B23: =B18-B22 -> 0 | C23: =C18-C22 -> 0 | D23: =D18-D22 -> 0 | E23: =E18-E22 -> 0 | F23: =F18-F22 -> 0 | G23: =G18-G22 -> 0 | H23: =H18-H22 -> 0 | I23: =I18-I22 -> 0 | ... L23: =L18-L22 -> 0
A25: 3. WORKING CAPITAL & CAPEX
A26: Change in Net Working Capital (negative = increase in NWC)
A27: Capital Expenditure (enter as negative)
A29: DEBT & QUASI-DEBT SCHEDULE
A30: Opening Debt Balance | B30: 0 | C30: =B33 -> 0 | D30: =C33 -> 0 | E30: =D33 -> 0 | F30: =E33 -> 0 | G30: =F33 -> 0 | H30: =G33 -> 0 | I30: =H33 -> 0 | J30: =I33 -> 0 | ... L30: =K33 -> 0
A31: New Debt Drawn
A32: Principal Repayment (enter as negative)
A33: Closing Debt Balance | B33: =SUM(B30:B32) -> 0 | C33: =SUM(C30:C32) -> 0 | D33: =SUM(D30:D32) -> 0 | E33: =SUM(E30:E32) -> 0 | F33: =SUM(F30:F32) -> 0 | G33: =SUM(G30:G32) -> 0 | H33: =SUM(H30:H32) -> 0 | I33: =SUM(I30:I32) -> 0 | ... L33: =SUM(L30:L32) -> 0
A35: Interest Rate on Debt (%)
A36: Interest Expense | B36: =(B30+B35)/2*B33/100 -> 0 | C36: =(C30+C35)/2*C33/100 -> 0 | D36: =(D30+D35)/2*D33/100 -> 0 | E36: =(E30+E35)/2*E33/100 -> 0 | F36: =(F30+F35)/2*F33/100 -> 0 | G36: =(G30+G35)/2*G33/100 -> 0 | H36: =(H30+H35)/2*H33/100 -> 0 | I36: =(I30+I35)/2*I33/100 -> 0 | ... L36: =(L30+L35)/2*L33/100 -> 0
A38: 5. FREE CASH FLOW BUILD-UP (FCFF & FCFE)
A39: FCFF Build-up:
A40: NOPAT (from Section 2) | B40: =B23 -> 0 | C40: =C23 -> 0 | D40: =D23 -> 0 | E40: =E23 -> 0 | F40: =F23 -> 0 | G40: =G23 -> 0 | H40: =H23 -> 0 | I40: =I23 -> 0 | ... L40: =L23 -> 0
A41: Add: Depreciation & Amortisation | B41: =B17 -> 0 | C41: =C17 -> 0 | D41: =D17 -> 0 | E41: =E17 -> 0 | F41: =F17 -> 0 | G41: =G17 -> 0 | H41: =H17 -> 0 | I41: =I17 -> 0 | ... L41: =L17 -> 0
A42: Add/Less: Change in Working Capital | B42: =B26 -> 0 | C42: =C26 -> 0 | D42: =D26 -> 0 | E42: =E26 -> 0 | F42: =F26 -> 0 | G42: =G26 -> 0 | H42: =H26 -> 0 | I42: =I26 -> 0 | ... L42: =L26 -> 0
A43: Less: Capital Expenditure | B43: =B27 -> 0 | C43: =C27 -> 0 | D43: =D27 -> 0 | E43: =E27 -> 0 | F43: =F27 -> 0 | G43: =G27 -> 0 | H43: =H27 -> 0 | I43: =I27 -> 0 | ... L43: =L27 -> 0
A44: Free Cash Flow to Firm (FCFF) | B44: =B40+B41+B42-B43 -> 0 | C44: =C40+C41+C42-C43 -> 0 | D44: =D40+D41+D42-D43 -> 0 | E44: =E40+E41+E42-E43 -> 0 | F44: =F40+F41+F42-F43 -> 0 | G44: =G40+G41+G42-G43 -> 0 | H44: =H40+H41+H42-H43 -> 0 | I44: =I40+I41+I42-I43 -> 0 | ... L44: =L40+L41+L42-L43 -> 0
A46: FCFE Build-up:
A47: FCFF (from above) | B47: =B44 -> 0 | C47: =C44 -> 0 | D47: =D44 -> 0 | E47: =E44 -> 0 | F47: =F44 -> 0 | G47: =G44 -> 0 | H47: =H44 -> 0 | I47: =I44 -> 0 | ... L47: =L44 -> 0
A48: Less: Interest Expense × (1 - Tax) | B48: =-B36 -> 0 | C48: =-C36 -> 0 | D48: =-D36 -> 0 | E48: =-E36 -> 0 | F48: =-F36 -> 0 | G48: =-G36 -> 0 | H48: =-H36 -> 0 | I48: =-I36 -> 0 | ... L48: =-L36 -> 0
A49: Less: Principal Repayment | B49: =B32 -> 0 | C49: =C32 -> 0 | D49: =D32 -> 0 | E49: =E32 -> 0 | F49: =F32 -> 0 | G49: =G32 -> 0 | H49: =H32 -> 0 | I49: =I32 -> 0 | ... L49: =L32 -> 0
A50: Add: New Debt Drawn | B50: =B31 -> 0 | C50: =C31 -> 0 | D50: =D31 -> 0 | E50: =E31 -> 0 | F50: =F31 -> 0 | G50: =G31 -> 0 | H50: =H31 -> 0 | I50: =I31 -> 0 | ... L50: =L31 -> 0
...

Sheet WACC_Inputs
A1: WACC INPUTS - COST OF CAPITAL BUILD-UP
A3: Note: WACC may be computed once (flat across forecast years) or year-by-year (reflecting changing capital structure). Default is flat.
A5: 1. CAPM BUILD-UP FOR COST OF EQUITY (Ke)
A6: Risk-Free Rate (Rf) — 10-Year G-Sec Yield (%)
A7: Equity Risk Premium (ERP, Rm-Rf) (%)
A8: Re-levered Beta (β)
A9: Industry Source for Beta (default: Aswath Damodaran (NYU Stern))
A10: Base Cost of Equity per CAPM = Rf + β × ERP (%) | B10: =B6+(B7*B8) -> 0
A12: Company-Specific Risk Premium (CSRP) (%)
A13: (CSRP for unlisted/small companies typically 5%-15%)
A15: Adjusted Cost of Equity (Ke) = Base CAPM + CSRP (%) | B15: =B10+B12 -> 0
A17: 2. DIRECT Ke OVERRIDE (used only if "Direct Ke" selected on Cover sheet)
A18: Direct Cost of Equity (%)
A19: (If 0 or blank, ValuAI uses CAPM build-up above. Otherwise, Direct Ke overrides.)
A21: 3. COST OF DEBT (Kd)
A22: Pre-Tax Cost of Debt (%)
A23: Effective Tax Rate (%) | B23: =Projections!B21 -> 0.25168
A24: Post-Tax Cost of Debt = Kd × (1 - Tax) (%) | B24: =B22*(1-B23) -> 0
A26: 4. CAPITAL STRUCTURE WEIGHTS
A27: Weight of Equity (We) (%)
A28: Weight of Debt (Wd) (%)
A29: Total (must equal 100%) | B29: =SUM(B27:B28) -> 0
A31: 5. WEIGHTED AVERAGE COST OF CAPITAL (WACC)
A32: Effective Ke (auto: CAPM if Direct = 0, else Direct) | B32: =IF(B18=0,B15,B18) -> 0
A33: Effective Kd (post-tax) | B33: =B24 -> 0
A34: WACC (Equity Component + Debt Component) (%) | B34: =B27*B32+B28*B33 -> 0
A36: 6. NOTES AND SOURCES
A37: Source for Risk-Free Rate | B37: RBI / FBIL 10-Year G-Sec Yield as on Valuation Date
A38: Source for Equity Risk Premium | B38: Aswath Damodaran, NYU Stern (adamodar@stern.nyu.edu)
A39: Source for Industry Beta | B39: Aswath Damodaran Industry Beta Tables
A40: Justification for CSRP
A41: Other Notes

Sheet Other_Inputs
A1: OTHER INPUTS - TERMINAL VALUE, SENSITIVITY & MISCELLANEOUS
A3: 1. TERMINAL VALUE PARAMETERS
A4: Terminal Value Method (from Cover sheet) | B4: =Cover!B37 -> Gordon Growth
A6: For Gordon Growth Method:
A7: Perpetual Growth Rate (g) (%)
A8: (Typically 2-6% for India; should not exceed long-term GDP growth)
A10: For Exit Multiple Method:
A11: Exit EBITDA Multiple (x)
A13: 2. SENSITIVITY ANALYSIS RANGES (for Tornado Chart)
A14: Driver | B14: Lower Variation (-) | C14: Upper Variation (+)
A15: WACC (% absolute change) | B15: -0.02 | C15: 0.02
A16: Terminal Growth Rate (% absolute change) | B16: -0.01 | C16: 0.01
A17: EBIT Margin (% relative change) | B17: -0.1 | C17: 0.1
A18: CAPEX (% relative change) | B18: -0.15 | C18: 0.15
A19: Working Capital Investment (% relative change) | B19: -0.2 | C19: 0.2
A21: Note: WACC and Terminal Growth use absolute % point changes (e.g., ±2 means WACC moves ±2 percentage points). EBIT, CAPEX, WC use relative % changes (e.g., -10 means EBIT margin reduced by 10% of itself).
A23: 3. DISCOUNT FOR LACK OF MARKETABILITY (DLOM)
A24: Apply DLOM? (Yes/No) | B24: No
A25: DLOM Percentage (%)
A26: (Typical range: 15-30% for unlisted equity per IBBI / IVS guidance)
A27: Justification for DLOM
A29: 4. DISCOUNT FOR LACK OF CONTROL (DLOC) — Minority Discount
A30: Apply DLOC? (Yes/No) | B30: No
A31: DLOC Percentage (%)
A32: (Typical range: 10-25% for unlisted equity per IBBI / IVS guidance)
A33: Justification for DLOC
A35: 5. METHOD WEIGHTAGES (for blending multiple methods)
A36: DCF (Income Approach) Weight (%) | B36: 1
A37: CCM (Market Approach - Comparable Companies) Weight (%) | B37: 0
A38: NAV (Cost Approach) Weight (%) | B38: 0
A39: Total Weight (must equal 100%) | B39: =SUM(B36:B38) -> 1
A40: Reasoning for Weights
A42: 6. PRE-MONEY / POST-MONEY RECONCILIATION
A43: Use Case (from Cover sheet) | B43: =Cover!B40 -> Standalone Valuation
A44: Investment Amount (from Cover sheet) | B44: =Cover!B41 -> 0
A45: Pre-Investment Shares (from Cover sheet) | B45: =Cover!B42 -> 0
A46: New Shares Issued (from Cover sheet) | B46: =Cover!B43 -> 0
A47: Post-Investment Shares (from Cover sheet) | B47: =Cover!B44 -> 0
A48: (Pre-money valuation = Post-money valuation - Investment Amount) | B48: 0

Sheet Comparables
A1: COMPARABLES (FOR MARKET APPROACH - CCM)
A3: Note: Enter up to 8 comparable listed companies. The CCM engine will compute median multiples and apply them to the subject company. Selection criteria should be documented for IBBI defensibility.
A5: 1. SUBJECT COMPANY METRICS (for applying multiples)
A6: Subject Company Revenue (latest year, in template units)
A7: Subject Company EBITDA (latest year)
A8: Subject Company EBIT (latest year)
A9: Subject Company PAT (latest year)
A10: Subject Company Book Value of Equity (latest year)
A12: 2. COMPARABLE COMPANIES TABLE
A13: S.No. | B13: Company Name | C13: Stock Exchange Symbol | D13: Industry / Sub-sector | E13: Market Cap (₹ Cr) | F13: Enterprise Value (₹ Cr) | G13: EV/Revenue | H13: EV/EBITDA | I13: EV/EBIT | J13: P/E | K13: P/B | L13: Selection Justification
A14: 1
A15: 2
A16: 3
A17: 4
A18: 5
A19: 6
A20: 7
A21: 8
A22: Median | G22: =IFERROR(MEDIAN(G14:G21),0) -> 0 | H22: =IFERROR(MEDIAN(H14:H21),0) -> 0 | I22: =IFERROR(MEDIAN(I14:I21),0) -> 0 | J22: =IFERROR(MEDIAN(J14:J21),0) -> 0 | K22: =IFERROR(MEDIAN(K14:K21),0) -> 0
A24: 3. MULTIPLE SELECTION & ADJUSTMENT
A25: Primary Multiple to Use | B25: EV/EBITDA
A26: Multiple Statistic | B26: Median
A27: Custom Multiple Value (used only if "Custom" selected above)
A29: Discount for Lack of Marketability on CCM (%)
A30: (Higher DLOM typically applied to CCM as multiples derive from listed liquid peers)
A31: Justification for DLOM
A33: Reference Information for User
A34: Recommended sources for peer data
A35: 1. NSE / BSE - For market cap and listed peer financials
A36: 2. Aswath Damodaran (NYU Stern) - For industry beta and sector multiples
A37: 3. Capitaline / Bloomberg / S&P Capital IQ - For curated multiples
